<?xml version="1.0" ?>
<!-- =================================================================================== -->
<!-- |    This document was autogenerated by xacro from robot.xacro                    | -->
<!-- |    EDITING THIS FILE BY HAND IS NOT RECOMMENDED                                 | -->
<!-- =================================================================================== -->
<robot name="diablo_rm">
  <material name="black">
    <color rgba="0.0 0.0 0.0 1.0"/>
  </material>
  <material name="blue">
    <color rgba="0.0 0.0 0.8 1.0"/>
  </material>
  <material name="green">
    <color rgba="0.0 0.8 0.0 1.0"/>
  </material>
  <material name="grey">
    <color rgba="0.2 0.2 0.2 1.0"/>
  </material>
  <material name="silver">
    <color rgba="0.9137254901960784 0.9137254901960784 0.8470588235294118 1.0"/>
  </material>
  <material name="orange">
    <color rgba="1.0 0.4235294117647059 0.0392156862745098 1.0"/>
  </material>
  <material name="brown">
    <color rgba="0.8705882352941177 0.8117647058823529 0.7647058823529411 1.0"/>
  </material>
  <material name="red">
    <color rgba="0.8 0.0 0.0 1.0"/>
  </material>
  <material name="white">
    <color rgba="1.0 1.0 1.0 1.0"/>
  </material>
  <link name="diablo_base_link">
    <inertial>
      <origin rpy="0 0 0" xyz="0 0 0"/>
      <mass value="11.639"/>
      <inertia ixx="0.071628" ixy="-5.9879e-09" ixz="-0.00097471" iyy="0.16274" iyz="-1.6369e-08" izz="0.14673"/>
    </inertial>
    <visual>
      <origin rpy="0 0 0" xyz="0 0 0"/>
      <geometry>
        <mesh filename="package://upright_asset/description/meshes/diablo/base_link.STL" scale="1 1 1"/>
      </geometry>
      <material name="grey"/>
    </visual>
    <collision>
      <origin rpy="0 0 0" xyz="0 0 0"/>
      <geometry>
        <mesh filename="package://upright_asset/description/meshes/diablo/base_link.STL" scale="1 1 1"/>
      </geometry>
    </collision>
  </link>
  <link name="left_motor">
    <inertial>
      <origin rpy="0 0 0" xyz="0 0 0"/>
      <mass value="1.3837"/>
      <inertia ixx="0.003352" ixy="2.7785e-09" ixz="-6.5913e-05" iyy="0.0034908" iyz="4.5045e-10" izz="0.0034856"/>
    </inertial>
    <visual>
      <origin rpy="0 0 0" xyz="0 0 0"/>
      <geometry>
        <mesh filename="package://upright_asset/description/meshes/diablo/left_motor.STL" scale="1 1 1"/>
      </geometry>
      <material name="silver"/>
    </visual>
    <collision>
      <origin rpy="0 0 0" xyz="0 0 0"/>
      <geometry>
        <mesh filename="package://upright_asset/description/meshes/diablo/left_motor.STL" scale="1 1 1"/>
      </geometry>
    </collision>
  </link>
  <link name="left_leg1">
    <inertial>
      <origin rpy="0 0 0" xyz="0 0 0"/>
      <mass value="0.10382"/>
      <inertia ixx="3.6972e-05" ixy="2.4106e-05" ixz="4.3699e-10" iyy="0.00029278" iyz="-4.1243e-11" izz="0.00032532"/>
    </inertial>
    <visual>
      <origin rpy="0 0 0" xyz="0 0 0"/>
      <geometry>
        <mesh filename="package://upright_asset/description/meshes/diablo/left_leg1.STL" scale="1 1 1"/>
      </geometry>
      <material name="silver"/>
    </visual>
    <collision>
      <origin rpy="0 0 0" xyz="0 0 0"/>
      <geometry>
        <mesh filename="package://upright_asset/description/meshes/diablo/left_leg1.STL" scale="1 1 1"/>
      </geometry>
    </collision>
  </link>
  <link name="left_leg2">
    <inertial>
      <origin rpy="0 0 0" xyz="0 0 0"/>
      <mass value="0.18218"/>
      <inertia ixx="4.1372e-05" ixy="5.1445e-09" ixz="-7.3659e-06" iyy="0.00048219" iyz="2.5521e-11" izz="0.00050441"/>
    </inertial>
    <visual>
      <origin rpy="0 0 0" xyz="0 0 0"/>
      <geometry>
        <mesh filename="package://upright_asset/description/meshes/diablo/left_leg2.STL" scale="1 1 1"/>
      </geometry>
      <material name="silver"/>
    </visual>
    <collision>
      <origin rpy="0 0 0" xyz="0 0 0"/>
      <geometry>
        <mesh filename="package://upright_asset/description/meshes/diablo/left_leg2.STL" scale="1 1 1"/>
      </geometry>
    </collision>
  </link>
  <link name="left_wheel">
    <inertial>
      <origin rpy="0 0 0" xyz="0 0 0"/>
      <mass value="2.9494"/>
      <inertia ixx="0.0069338" ixy="2.8693e-09" ixz="4.6779e-09" iyy="0.006934" iyz="-5.0441e-11" izz="0.012567"/>
    </inertial>
    <visual>
      <origin rpy="0 0 0" xyz="0 0 0"/>
      <geometry>
        <mesh filename="package://upright_asset/description/meshes/diablo/left_wheel.STL" scale="1 1 1"/>
      </geometry>
      <material name="black"/>
    </visual>
    <collision>
      <origin rpy="0 0 0" xyz="0 0 0"/>
      <geometry>
        <mesh filename="package://upright_asset/description/meshes/diablo/left_wheel.STL" scale="1 1 1"/>
      </geometry>
    </collision>
  </link>
  <link name="left_leg3">
    <inertial>
      <origin rpy="0 0 0" xyz="0 0 0"/>
      <mass value="0.071103"/>
      <inertia ixx="1.6657e-05" ixy="-5.5246e-06" ixz="3.9598e-14" iyy="0.00017966" iyz="-6.5493e-15" izz="0.00019328"/>
    </inertial>
    <visual>
      <origin rpy="0 0 0" xyz="0 0 0"/>
      <geometry>
        <mesh filename="package://upright_asset/description/meshes/diablo/left_leg3.STL" scale="1 1 1"/>
      </geometry>
      <material name="brown"/>
    </visual>
    <collision>
      <origin rpy="0 0 0" xyz="0 0 0"/>
      <geometry>
        <mesh filename="package://upright_asset/description/meshes/diablo/left_leg3.STL" scale="1 1 1"/>
      </geometry>
    </collision>
  </link>
  <link name="right_motor">
    <inertial>
      <origin rpy="0 0 0" xyz="0 0 0"/>
      <mass value="1.3838"/>
      <inertia ixx="0.003352" ixy="-2.6527e-09" ixz="6.5914e-05" iyy="0.0034908" iyz="-7.2968e-10" izz="0.0034856"/>
    </inertial>
    <visual>
      <origin rpy="0 0 0" xyz="0 0 0"/>
      <geometry>
        <mesh filename="package://upright_asset/description/meshes/diablo/right_motor.STL" scale="1 1 1"/>
      </geometry>
      <material name="silver"/>
    </visual>
    <collision>
      <origin rpy="0 0 0" xyz="0 0 0"/>
      <geometry>
        <mesh filename="package://upright_asset/description/meshes/diablo/right_motor.STL" scale="1 1 1"/>
      </geometry>
    </collision>
  </link>
  <link name="right_leg1">
    <inertial>
      <origin rpy="0 0 0" xyz="0 0 0"/>
      <mass value="0.10382"/>
      <inertia ixx="3.6972e-05" ixy="2.4106e-05" ixz="-4.3686e-10" iyy="0.00029278" iyz="4.1459e-11" izz="0.00032532"/>
    </inertial>
    <visual>
      <origin rpy="0 0 0" xyz="0 0 0"/>
      <geometry>
        <mesh filename="package://upright_asset/description/meshes/diablo/right_leg1.STL" scale="1 1 1"/>
      </geometry>
      <material name="silver"/>
    </visual>
    <collision>
      <origin rpy="0 0 0" xyz="0 0 0"/>
      <geometry>
        <mesh filename="package://upright_asset/description/meshes/diablo/right_leg1.STL" scale="1 1 1"/>
      </geometry>
    </collision>
  </link>
  <link name="right_leg2">
    <inertial>
      <origin rpy="0 0 0" xyz="0 0 0"/>
      <mass value="0.18218"/>
      <inertia ixx="4.1372e-05" ixy="5.1777e-09" ixz="7.3659e-06" iyy="0.00048219" iyz="4.5225e-11" izz="0.00050441"/>
    </inertial>
    <visual>
      <origin rpy="0 0 0" xyz="0 0 0"/>
      <geometry>
        <mesh filename="package://upright_asset/description/meshes/diablo/right_leg2.STL" scale="1 1 1"/>
      </geometry>
      <material name="silver"/>
    </visual>
    <collision>
      <origin rpy="0 0 0" xyz="0 0 0"/>
      <geometry>
        <mesh filename="package://upright_asset/description/meshes/diablo/right_leg2.STL" scale="1 1 1"/>
      </geometry>
    </collision>
  </link>
  <link name="right_wheel">
    <inertial>
      <origin rpy="0 0 0" xyz="0 0 0"/>
      <mass value="2.9494"/>
      <inertia ixx="0.0069339" ixy="-1.3146e-07" ixz="-3.0392e-09" iyy="0.0069339" iyz="-3.5756e-09" izz="0.012567"/>
    </inertial>
    <visual>
      <origin rpy="0 0 0" xyz="0 0 0"/>
      <geometry>
        <mesh filename="package://upright_asset/description/meshes/diablo/right_wheel.STL" scale="1 1 1"/>
      </geometry>
      <material name="black"/>
    </visual>
    <collision>
      <origin rpy="0 0 0" xyz="0 0 0"/>
      <geometry>
        <mesh filename="package://upright_asset/description/meshes/diablo/right_wheel.STL" scale="1 1 1"/>
      </geometry>
    </collision>
  </link>
  <link name="right_leg3">
    <inertial>
      <origin rpy="0 0 0" xyz="0 0 0"/>
      <mass value="0.071103"/>
      <inertia ixx="1.6657e-05" ixy="-5.5246e-06" ixz="1.4852e-14" iyy="0.00017966" iyz="-6.5194e-14" izz="0.00019328"/>
    </inertial>
    <visual>
      <origin rpy="0 0 0" xyz="0 0 0"/>
      <geometry>
        <mesh filename="package://upright_asset/description/meshes/diablo/right_leg3.STL" scale="1 1 1"/>
      </geometry>
      <material name="brown"/>
    </visual>
    <collision>
      <origin rpy="0 0 0" xyz="0 0 0"/>
      <geometry>
        <mesh filename="package://upright_asset/description/meshes/diablo/right_leg3.STL" scale="1 1 1"/>
      </geometry>
    </collision>
  </link>
  <joint name="left_j4" type="continuous">
    <origin rpy="1.5708 0.13433 -3.1416" xyz="0 0.18755 0"/>
    <parent link="diablo_base_link"/>
    <child link="left_motor"/>
  </joint>
  <joint name="left_j1" type="continuous">
    <origin rpy="0 0 -2.8729" xyz="0 0 0"/>
    <parent link="left_motor"/>
    <child link="left_leg1"/>
  </joint>
  <joint name="left_j2" type="continuous">
    <origin rpy="0 0 2.8729" xyz="0.14 0 0"/>
    <parent link="left_leg1"/>
    <child link="left_leg2"/>
  </joint>
  <joint name="left_j3" type="continuous">
    <origin rpy="0 0 0.13433" xyz="0.14 0 0.0537"/>
    <parent link="left_leg2"/>
    <child link="left_wheel"/>
  </joint>
  <joint name="left_j5" type="continuous">
    <origin rpy="0 0 -2.8729" xyz="0.09 0 0"/>
    <parent link="left_motor"/>
    <child link="left_leg3"/>
  </joint>
  <joint name="right_j4" type="continuous">
    <origin rpy="1.5708 0.13433 3.1416" xyz="0 -0.18755 0"/>
    <parent link="diablo_base_link"/>
    <child link="right_motor"/>
  </joint>
  <joint name="right_j1" type="continuous">
    <origin rpy="0 0 -2.8729" xyz="0 0 0"/>
    <parent link="right_motor"/>
    <child link="right_leg1"/>
  </joint>
  <joint name="right_j2" type="continuous">
    <origin rpy="0 0 2.8729" xyz="0.14 0 0"/>
    <parent link="right_leg1"/>
    <child link="right_leg2"/>
  </joint>
  <joint name="right_j3" type="continuous">
    <origin rpy="0 0 -3.0073" xyz="0.14 0 -0.0537"/>
    <parent link="right_leg2"/>
    <child link="right_wheel"/>
  </joint>
  <joint name="right_j5" type="continuous">
    <origin rpy="0 0 -2.8729" xyz="0.09 0 0"/>
    <parent link="right_motor"/>
    <child link="right_leg3"/>
  </joint>
  <!--TODO： Add close-chian -->
  <gazebo>
    <joint name="left_close_chain" type="continuous">
      <origin rpy="0 0 0" xyz="0.1 0 0"/>
      <parent link="left_leg3"/>
      <child link="left_leg2"/>
    </joint>
    <joint name="right_close_chain" type="continuous">
      <origin rpy="0 0 0" xyz="0.1 0 0"/>
      <parent link="right_leg3"/>
      <child link="right_leg2"/>
    </joint>
  </gazebo>
  <!-- Finish defining the robot's structure with all links and joints accurately reflecting the URDF structure -->
  <!-- ros_control plugin -->
  <!-- <gazebo>
        <plugin name="gazebo_ros_control" filename="liblegged_hw_sim.so">
            <robotNamespace>/</robotNamespace>
            <robotParam>legged_robot_description</robotParam>
            <robotSimType>legged_gazebo/LeggedHWSim</robotSimType>
        </plugin>
    </gazebo> -->
  <gazebo>
    <plugin filename="libgazebo_ros_p3d.so" name="p3d_base_controller">
      <alwaysOn>true</alwaysOn>
      <updateRate>1000.0</updateRate>
      <bodyName>diablo_base_link</bodyName>
      <topicName>ground_truth/state</topicName>
      <gaussianNoise>0</gaussianNoise>
      <frameName>world</frameName>
      <xyzOffsets>0 0 0</xyzOffsets>
      <rpyOffsets>0 0 0</rpyOffsets>
    </plugin>
  </gazebo>
  <!--    <xacro:include filename="$(find upright_asset)/description/urdf/diablo/imu.xacro"/>-->
  <!-- ///////////////////////////////////////   bottom_joint   ////////////////////////////////////////// -->
  <link name="arm_base_link">
    <inertial>
      <origin rpy="0 0 0" xyz="-0.000433277303987328 -3.54664423471128E-05 0.0599427668933796"/>
      <mass value="0.841070778135659"/>
      <inertia ixx="0.0017261110801622" ixy="2.52746264980217E-06" ixz="-3.67690303614961E-05" iyy="0.00170987405835604" iyz="1.67996364994424E-06" izz="0.000904023422915791"/>
    </inertial>
    <visual>
      <origin rpy="0 0 0" xyz="0 0 0"/>
      <geometry>
        <mesh filename="package://upright_asset/description/meshes/RM65/base_link.STL"/>
      </geometry>
      <material name="">
        <color rgba="1 1 1 1"/>
      </material>
    </visual>
    <collision>
      <origin rpy="0 0 0" xyz="0 0 0"/>
      <geometry>
        <mesh filename="package://upright_asset/description/meshes/RM65/base_link.STL"/>
      </geometry>
    </collision>
  </link>
  <link name="Link1">
    <inertial>
      <origin rpy="0 0 0" xyz="1.2226305431569E-08 0.0211079974844683 -0.0251854220842269"/>
      <mass value="0.593563443690403"/>
      <inertia ixx="0.00126614120341847" ixy="-1.294980943835E-08" ixz="-9.80120923066996E-09" iyy="0.00118168178300364" iyz="-0.00021121727444415" izz="0.00056135241627747"/>
    </inertial>
    <visual>
      <origin rpy="0 0 0" xyz="0 0 0"/>
      <geometry>
        <mesh filename="package://upright_asset/description/meshes/RM65/link1.STL"/>
      </geometry>
      <material name="">
        <color rgba="1 1 1 1"/>
      </material>
    </visual>
    <collision>
      <origin rpy="0 0 0" xyz="0 0 0"/>
      <geometry>
        <mesh filename="package://upright_asset/description/meshes/RM65/link1.STL"/>
      </geometry>
    </collision>
  </link>
  <joint name="joint1" type="revolute">
    <origin rpy="0 0 0" xyz="0 0 0.2405"/>
    <parent link="arm_base_link"/>
    <child link="Link1"/>
    <axis xyz="0 0 1"/>
    <limit effort="60" lower="-3.1" upper="3.1" velocity="3.14"/>
    <dynamics damping="50" friction="1"/>
  </joint>
  <link name="Link2">
    <inertial>
      <origin rpy="0 0 0" xyz="0.152256463426163 4.75383656106654E-07 -0.00620260383607792"/>
      <mass value="0.864175046869043"/>
      <inertia ixx="0.00089150298478414" ixy="-2.23268489334765E-08" ixz="0.00156246461035015" iyy="0.00733754343083901" iyz="6.28110889329165E-09" izz="0.00697869103915473"/>
    </inertial>
    <visual>
      <origin rpy="0 0 0" xyz="0 0 0"/>
      <geometry>
        <mesh filename="package://upright_asset/description/meshes/RM65/link2.STL"/>
      </geometry>
      <material name="">
        <color rgba="1 1 1 1"/>
      </material>
    </visual>
    <collision>
      <origin rpy="0 0 0" xyz="0 0 0"/>
      <geometry>
        <mesh filename="package://upright_asset/description/meshes/RM65/link2.STL"/>
      </geometry>
    </collision>
  </link>
  <joint name="joint2" type="revolute">
    <origin rpy="1.5708 -1.5708 0" xyz="0 0 0"/>
    <parent link="Link1"/>
    <child link="Link2"/>
    <axis xyz="0 0 1"/>
    <limit effort="60" lower="-2.268" upper="2.268" velocity="3.14"/>
    <dynamics damping="50" friction="1"/>
  </joint>
  <link name="Link3">
    <inertial>
      <origin rpy="0 0 0" xyz="5.05312670989961E-06 -0.0595925663694732 0.010569069212336"/>
      <mass value="0.289633681624654"/>
      <inertia ixx="0.00063737100450158" ixy="-7.05261293649751E-08" ixz="-3.86643272239426E-08" iyy="0.00015648388095025" iyz="-0.00014461035994916" izz="0.000614178164773085"/>
    </inertial>
    <visual>
      <origin rpy="0 0 0" xyz="0 0 0"/>
      <geometry>
        <mesh filename="package://upright_asset/description/meshes/RM65/link3.STL"/>
      </geometry>
      <material name="">
        <color rgba="1 1 1 1"/>
      </material>
    </visual>
    <collision>
      <origin rpy="0 0 0" xyz="0 0 0"/>
      <geometry>
        <mesh filename="package://upright_asset/description/meshes/RM65/link3.STL"/>
      </geometry>
    </collision>
  </link>
  <joint name="joint3" type="revolute">
    <origin rpy="0 0 1.5708" xyz="0.256 0 0"/>
    <parent link="Link2"/>
    <child link="Link3"/>
    <axis xyz="0 0 1"/>
    <limit effort="30" lower="-2.355" upper="2.355" velocity="3.92"/>
    <dynamics damping="50" friction="1"/>
  </joint>
  <link name="Link4">
    <inertial>
      <origin rpy="0 0 0" xyz="1.15516617405898E-06 -0.0180424468598241 -0.0215394748352687"/>
      <mass value="0.239419768320061"/>
      <inertia ixx="0.000285938919722783" ixy="3.07101359163101E-09" ixz="-2.21994118981953E-09" iyy="0.000262727540304212" iyz="4.4236583260078E-05" izz="0.000119888082791859"/>
    </inertial>
    <visual>
      <origin rpy="0 0 0" xyz="0 0 0"/>
      <geometry>
        <mesh filename="package://upright_asset/description/meshes/RM65/link4.STL"/>
      </geometry>
      <material name="">
        <color rgba="1 1 1 1"/>
      </material>
    </visual>
    <collision>
      <origin rpy="0 0 0" xyz="0 0 0"/>
      <geometry>
        <mesh filename="package://upright_asset/description/meshes/RM65/link4.STL"/>
      </geometry>
    </collision>
  </link>
  <joint name="joint4" type="revolute">
    <origin rpy="1.5708 0 0" xyz="0 -0.21 0"/>
    <parent link="Link3"/>
    <child link="Link4"/>
    <axis xyz="0 0 1"/>
    <limit effort="10" lower="-3.1" upper="3.1" velocity="3.92"/>
    <dynamics damping="50" friction="1"/>
  </joint>
  <link name="Link5">
    <inertial>
      <origin rpy="0 0 0" xyz="3.19794786262152E-06 -0.0593808368101458 0.00736804250989326"/>
      <mass value="0.218799761431678"/>
      <inertia ixx="0.000350540363914072" ixy="-3.41781619975602E-08" ixz="-1.77056457224373E-08" iyy="0.000104927867487581" iyz="-7.82431228461971E-05" izz="0.000334482418423629"/>
    </inertial>
    <visual>
      <origin rpy="0 0 0" xyz="0 0 0"/>
      <geometry>
        <mesh filename="package://upright_asset/description/meshes/RM65/link5.STL"/>
      </geometry>
      <material name="">
        <color rgba="1 1 1 1"/>
      </material>
    </visual>
    <collision>
      <origin rpy="0 0 0" xyz="0 0 0"/>
      <geometry>
        <mesh filename="package://upright_asset/description/meshes/RM65/link5.STL"/>
      </geometry>
    </collision>
  </link>
  <joint name="joint5" type="revolute">
    <origin rpy="-1.5708 0 0" xyz="0 0 0"/>
    <parent link="Link4"/>
    <child link="Link5"/>
    <axis xyz="0 0 1"/>
    <limit effort="10" lower="-2.233" upper="2.233" velocity="3.92"/>
    <dynamics damping="50" friction="1"/>
  </joint>
  <link name="Link6">
    <inertial>
      <origin rpy="0 0 0" xyz="0.000714234511756999 -0.000396718732824521 -0.0126723660946126"/>
      <mass value="0.0649018034311231"/>
      <inertia ixx="2.02766547502765E-05" ixy="-1.32505200276849E-06" ixz="-2.5845091522508E-08" iyy="1.87986725225022E-05" iyz="3.39471452125439E-09" izz="3.17885459163081E-05"/>
    </inertial>
    <visual>
      <origin rpy="0 0 0" xyz="0 0 0"/>
      <geometry>
        <mesh filename="package://upright_asset/description/meshes/RM65/link6.STL"/>
      </geometry>
      <material name="">
        <color rgba="1 1 1 1"/>
      </material>
    </visual>
    <collision>
      <origin rpy="0 0 0" xyz="0 0 0"/>
      <geometry>
        <mesh filename="package://upright_asset/description/meshes/RM65/link6.STL"/>
      </geometry>
    </collision>
  </link>
  <joint name="joint6" type="revolute">
    <origin rpy="1.5708 0 0" xyz="0 -0.144 0"/>
    <parent link="Link5"/>
    <child link="Link6"/>
    <axis xyz="0 0 1"/>
    <limit effort="10" lower="-6.28" upper="6.28" velocity="3.92"/>
    <dynamics damping="50" friction="1"/>
  </joint>
  <transmission name="tran1">
    <type>transmission_interface/SimpleTransmission</type>
    <joint name="joint1">
      <hardwareInterface>hardware_interface/PositionJointInterface</hardwareInterface>
    </joint>
    <actuator name="motor1">
      <hardwareInterface>hardware_interface/PositionJointInterface</hardwareInterface>
      <mechanicalReduction>1</mechanicalReduction>
    </actuator>
  </transmission>
  <transmission name="tran1">
    <type>transmission_interface/SimpleTransmission</type>
    <joint name="joint2">
      <hardwareInterface>hardware_interface/PositionJointInterface</hardwareInterface>
    </joint>
    <actuator name="motor1">
      <hardwareInterface>hardware_interface/PositionJointInterface</hardwareInterface>
      <mechanicalReduction>1</mechanicalReduction>
    </actuator>
  </transmission>
  <transmission name="tran1">
    <type>transmission_interface/SimpleTransmission</type>
    <joint name="joint3">
      <hardwareInterface>hardware_interface/PositionJointInterface</hardwareInterface>
    </joint>
    <actuator name="motor1">
      <hardwareInterface>hardware_interface/PositionJointInterface</hardwareInterface>
      <mechanicalReduction>1</mechanicalReduction>
    </actuator>
  </transmission>
  <transmission name="tran1">
    <type>transmission_interface/SimpleTransmission</type>
    <joint name="joint4">
      <hardwareInterface>hardware_interface/PositionJointInterface</hardwareInterface>
    </joint>
    <actuator name="motor1">
      <hardwareInterface>hardware_interface/PositionJointInterface</hardwareInterface>
      <mechanicalReduction>1</mechanicalReduction>
    </actuator>
  </transmission>
  <transmission name="tran1">
    <type>transmission_interface/SimpleTransmission</type>
    <joint name="joint5">
      <hardwareInterface>hardware_interface/PositionJointInterface</hardwareInterface>
    </joint>
    <actuator name="motor1">
      <hardwareInterface>hardware_interface/PositionJointInterface</hardwareInterface>
      <mechanicalReduction>1</mechanicalReduction>
    </actuator>
  </transmission>
  <transmission name="tran1">
    <type>transmission_interface/SimpleTransmission</type>
    <joint name="joint6">
      <hardwareInterface>hardware_interface/PositionJointInterface</hardwareInterface>
    </joint>
    <actuator name="motor1">
      <hardwareInterface>hardware_interface/PositionJointInterface</hardwareInterface>
      <mechanicalReduction>1</mechanicalReduction>
    </actuator>
  </transmission>
  <!-- ros_control plugin -->
  <gazebo>
    <plugin filename="libgazebo_ros_control.so" name="gazebo_ros_control">
      <robotNamespace>/arm</robotNamespace>
      <robotSimType>gazebo_ros_control/DefaultRobotHWSim</robotSimType>
      <legacyModeNS>true</legacyModeNS>
    </plugin>
  </gazebo>
  <joint name="manipulator_joint" type="fixed">
    <parent link="diablo_base_link"/>
    <child link="arm_base_link"/>
    <origin rpy="0.0 0.0 3.14" xyz="0.0 0.0 0.1"/>
  </joint>
  <gazebo>
    <plugin filename="libgazebo_ros_p3d.so" name="p3d_base_controller">
      <alwaysOn>true</alwaysOn>
      <updateRate>1000.0</updateRate>
      <bodyName>diablo_base_link</bodyName>
      <topicName>ground_truth/state</topicName>
      <gaussianNoise>0</gaussianNoise>
      <frameName>world</frameName>
      <xyzOffsets>0 0 0</xyzOffsets>
      <rpyOffsets>0 0 0</rpyOffsets>
    </plugin>
  </gazebo>
  <!-- ros_control plugin -->
  <!--    <gazebo>-->
  <!--        <plugin name="gazebo_ros_control" filename="libqm_hw_sim.so">-->
  <!--            <robotNamespace>/</robotNamespace>-->
  <!--            <robotParam>upright_asset</robotParam>-->
  <!--            <robotSimType>qm_gazebo/QMHWSim</robotSimType>-->
  <!--        </plugin>-->
  <!--    </gazebo>-->
</robot>

