<?xml version="1.0" ?>
<!-- =================================================================================== -->
<!-- |    This document was autogenerated by xacro from robot_pinocchio.xacro          | -->
<!-- |    EDITING THIS FILE BY HAND IS NOT RECOMMENDED                                 | -->
<!-- =================================================================================== -->
<robot name="diablo_swingboy">
  <material name="black">
    <color rgba="0.0 0.0 0.0 1.0"/>
  </material>
  <material name="blue">
    <color rgba="0.0 0.0 0.8 1.0"/>
  </material>
  <material name="green">
    <color rgba="0.0 0.8 0.0 1.0"/>
  </material>
  <material name="grey">
    <color rgba="0.2 0.2 0.2 1.0"/>
  </material>
  <material name="silver">
    <color rgba="0.9137254901960784 0.9137254901960784 0.8470588235294118 1.0"/>
  </material>
  <material name="orange">
    <color rgba="1.0 0.4235294117647059 0.0392156862745098 1.0"/>
  </material>
  <material name="brown">
    <color rgba="0.8705882352941177 0.8117647058823529 0.7647058823529411 1.0"/>
  </material>
  <material name="red">
    <color rgba="0.8 0.0 0.0 1.0"/>
  </material>
  <material name="white">
    <color rgba="1.0 1.0 1.0 1.0"/>
  </material>
  <link name="diablo_base_link">
    <inertial>
      <origin rpy="0 0 0" xyz="0 0 0"/>
      <mass value="11.639"/>
      <inertia ixx="0.071628" ixy="-5.9879e-09" ixz="-0.00097471" iyy="0.16274" iyz="-1.6369e-08" izz="0.14673"/>
    </inertial>
    <visual>
      <origin rpy="0 0 0" xyz="0 0 0"/>
      <geometry>
        <mesh filename="package://upright_asset/description/meshes/diablo/base_link.STL" scale="1 1 1"/>
      </geometry>
      <material name="grey"/>
    </visual>
    <collision>
      <origin rpy="0 0 0" xyz="0 0 0"/>
      <geometry>
        <mesh filename="package://upright_asset/description/meshes/diablo/base_link.STL" scale="1 1 1"/>
      </geometry>
    </collision>
  </link>
  <link name="left_motor">
    <inertial>
      <origin rpy="0 0 0" xyz="0 0 0"/>
      <mass value="1.3837"/>
      <inertia ixx="0.003352" ixy="2.7785e-09" ixz="-6.5913e-05" iyy="0.0034908" iyz="4.5045e-10" izz="0.0034856"/>
    </inertial>
    <visual>
      <origin rpy="0 0 0" xyz="0 0 0"/>
      <geometry>
        <mesh filename="package://upright_asset/description/meshes/diablo/left_motor.STL" scale="1 1 1"/>
      </geometry>
      <material name="silver"/>
    </visual>
    <collision>
      <origin rpy="0 0 0" xyz="0 0 0"/>
      <geometry>
        <mesh filename="package://upright_asset/description/meshes/diablo/left_motor.STL" scale="1 1 1"/>
      </geometry>
    </collision>
  </link>
  <link name="left_leg1">
    <inertial>
      <origin rpy="0 0 0" xyz="0 0 0"/>
      <mass value="0.10382"/>
      <inertia ixx="3.6972e-05" ixy="2.4106e-05" ixz="4.3699e-10" iyy="0.00029278" iyz="-4.1243e-11" izz="0.00032532"/>
    </inertial>
    <visual>
      <origin rpy="0 0 0" xyz="0 0 0"/>
      <geometry>
        <mesh filename="package://upright_asset/description/meshes/diablo/left_leg1.STL" scale="1 1 1"/>
      </geometry>
      <material name="silver"/>
    </visual>
    <collision>
      <origin rpy="0 0 0" xyz="0 0 0"/>
      <geometry>
        <mesh filename="package://upright_asset/description/meshes/diablo/left_leg1.STL" scale="1 1 1"/>
      </geometry>
    </collision>
  </link>
  <link name="left_leg2">
    <inertial>
      <origin rpy="0 0 0" xyz="0 0 0"/>
      <mass value="0.18218"/>
      <inertia ixx="4.1372e-05" ixy="5.1445e-09" ixz="-7.3659e-06" iyy="0.00048219" iyz="2.5521e-11" izz="0.00050441"/>
    </inertial>
    <visual>
      <origin rpy="0 0 0" xyz="0 0 0"/>
      <geometry>
        <mesh filename="package://upright_asset/description/meshes/diablo/left_leg2.STL" scale="1 1 1"/>
      </geometry>
      <material name="silver"/>
    </visual>
    <collision>
      <origin rpy="0 0 0" xyz="0 0 0"/>
      <geometry>
        <mesh filename="package://upright_asset/description/meshes/diablo/left_leg2.STL" scale="1 1 1"/>
      </geometry>
    </collision>
  </link>
  <link name="left_wheel">
    <inertial>
      <origin rpy="0 0 0" xyz="0 0 0"/>
      <mass value="2.9494"/>
      <inertia ixx="0.0069338" ixy="2.8693e-09" ixz="4.6779e-09" iyy="0.006934" iyz="-5.0441e-11" izz="0.012567"/>
    </inertial>
    <visual>
      <origin rpy="0 0 0" xyz="0 0 0"/>
      <geometry>
        <mesh filename="package://upright_asset/description/meshes/diablo/left_wheel.STL" scale="1 1 1"/>
      </geometry>
      <material name="black"/>
    </visual>
    <collision>
      <origin rpy="0 0 0" xyz="0 0 0"/>
      <geometry>
        <mesh filename="package://upright_asset/description/meshes/diablo/left_wheel.STL" scale="1 1 1"/>
      </geometry>
    </collision>
  </link>
  <link name="left_leg3">
    <inertial>
      <origin rpy="0 0 0" xyz="0 0 0"/>
      <mass value="0.071103"/>
      <inertia ixx="1.6657e-05" ixy="-5.5246e-06" ixz="3.9598e-14" iyy="0.00017966" iyz="-6.5493e-15" izz="0.00019328"/>
    </inertial>
    <visual>
      <origin rpy="0 0 0" xyz="0 0 0"/>
      <geometry>
        <mesh filename="package://upright_asset/description/meshes/diablo/left_leg3.STL" scale="1 1 1"/>
      </geometry>
      <material name="brown"/>
    </visual>
    <collision>
      <origin rpy="0 0 0" xyz="0 0 0"/>
      <geometry>
        <mesh filename="package://upright_asset/description/meshes/diablo/left_leg3.STL" scale="1 1 1"/>
      </geometry>
    </collision>
  </link>
  <link name="right_motor">
    <inertial>
      <origin rpy="0 0 0" xyz="0 0 0"/>
      <mass value="1.3838"/>
      <inertia ixx="0.003352" ixy="-2.6527e-09" ixz="6.5914e-05" iyy="0.0034908" iyz="-7.2968e-10" izz="0.0034856"/>
    </inertial>
    <visual>
      <origin rpy="0 0 0" xyz="0 0 0"/>
      <geometry>
        <mesh filename="package://upright_asset/description/meshes/diablo/right_motor.STL" scale="1 1 1"/>
      </geometry>
      <material name="silver"/>
    </visual>
    <collision>
      <origin rpy="0 0 0" xyz="0 0 0"/>
      <geometry>
        <mesh filename="package://upright_asset/description/meshes/diablo/right_motor.STL" scale="1 1 1"/>
      </geometry>
    </collision>
  </link>
  <link name="right_leg1">
    <inertial>
      <origin rpy="0 0 0" xyz="0 0 0"/>
      <mass value="0.10382"/>
      <inertia ixx="3.6972e-05" ixy="2.4106e-05" ixz="-4.3686e-10" iyy="0.00029278" iyz="4.1459e-11" izz="0.00032532"/>
    </inertial>
    <visual>
      <origin rpy="0 0 0" xyz="0 0 0"/>
      <geometry>
        <mesh filename="package://upright_asset/description/meshes/diablo/right_leg1.STL" scale="1 1 1"/>
      </geometry>
      <material name="silver"/>
    </visual>
    <collision>
      <origin rpy="0 0 0" xyz="0 0 0"/>
      <geometry>
        <mesh filename="package://upright_asset/description/meshes/diablo/right_leg1.STL" scale="1 1 1"/>
      </geometry>
    </collision>
  </link>
  <link name="right_leg2">
    <inertial>
      <origin rpy="0 0 0" xyz="0 0 0"/>
      <mass value="0.18218"/>
      <inertia ixx="4.1372e-05" ixy="5.1777e-09" ixz="7.3659e-06" iyy="0.00048219" iyz="4.5225e-11" izz="0.00050441"/>
    </inertial>
    <visual>
      <origin rpy="0 0 0" xyz="0 0 0"/>
      <geometry>
        <mesh filename="package://upright_asset/description/meshes/diablo/right_leg2.STL" scale="1 1 1"/>
      </geometry>
      <material name="silver"/>
    </visual>
    <collision>
      <origin rpy="0 0 0" xyz="0 0 0"/>
      <geometry>
        <mesh filename="package://upright_asset/description/meshes/diablo/right_leg2.STL" scale="1 1 1"/>
      </geometry>
    </collision>
  </link>
  <link name="right_wheel">
    <inertial>
      <origin rpy="0 0 0" xyz="0 0 0"/>
      <mass value="2.9494"/>
      <inertia ixx="0.0069339" ixy="-1.3146e-07" ixz="-3.0392e-09" iyy="0.0069339" iyz="-3.5756e-09" izz="0.012567"/>
    </inertial>
    <visual>
      <origin rpy="0 0 0" xyz="0 0 0"/>
      <geometry>
        <mesh filename="package://upright_asset/description/meshes/diablo/right_wheel.STL" scale="1 1 1"/>
      </geometry>
      <material name="black"/>
    </visual>
    <collision>
      <origin rpy="0 0 0" xyz="0 0 0"/>
      <geometry>
        <mesh filename="package://upright_asset/description/meshes/diablo/right_wheel.STL" scale="1 1 1"/>
      </geometry>
    </collision>
  </link>
  <link name="right_leg3">
    <inertial>
      <origin rpy="0 0 0" xyz="0 0 0"/>
      <mass value="0.071103"/>
      <inertia ixx="1.6657e-05" ixy="-5.5246e-06" ixz="1.4852e-14" iyy="0.00017966" iyz="-6.5194e-14" izz="0.00019328"/>
    </inertial>
    <visual>
      <origin rpy="0 0 0" xyz="0 0 0"/>
      <geometry>
        <mesh filename="package://upright_asset/description/meshes/diablo/right_leg3.STL" scale="1 1 1"/>
      </geometry>
      <material name="brown"/>
    </visual>
    <collision>
      <origin rpy="0 0 0" xyz="0 0 0"/>
      <geometry>
        <mesh filename="package://upright_asset/description/meshes/diablo/right_leg3.STL" scale="1 1 1"/>
      </geometry>
    </collision>
  </link>
  <joint name="left_j4" type="fixed">
    <origin rpy="1.5708 0.13433 -3.1416" xyz="0 0.18755 0"/>
    <parent link="diablo_base_link"/>
    <child link="left_motor"/>
  </joint>
  <joint name="left_j1" type="fixed">
    <origin rpy="0 0 -2.8729" xyz="0 0 0"/>
    <parent link="left_motor"/>
    <child link="left_leg1"/>
  </joint>
  <joint name="left_j2" type="fixed">
    <origin rpy="0 0 2.8729" xyz="0.14 0 0"/>
    <parent link="left_leg1"/>
    <child link="left_leg2"/>
  </joint>
  <joint name="left_j3" type="fixed">
    <origin rpy="0 0 0.13433" xyz="0.14 0 0.0537"/>
    <parent link="left_leg2"/>
    <child link="left_wheel"/>
  </joint>
  <joint name="left_j5" type="fixed">
    <origin rpy="0 0 -2.8729" xyz="0.09 0 0"/>
    <parent link="left_motor"/>
    <child link="left_leg3"/>
  </joint>
  <joint name="right_j4" type="fixed">
    <origin rpy="1.5708 0.13433 3.1416" xyz="0 -0.18755 0"/>
    <parent link="diablo_base_link"/>
    <child link="right_motor"/>
  </joint>
  <joint name="right_j1" type="fixed">
    <origin rpy="0 0 -2.8729" xyz="0 0 0"/>
    <parent link="right_motor"/>
    <child link="right_leg1"/>
  </joint>
  <joint name="right_j2" type="fixed">
    <origin rpy="0 0 2.8729" xyz="0.14 0 0"/>
    <parent link="right_leg1"/>
    <child link="right_leg2"/>
  </joint>
  <joint name="right_j3" type="fixed">
    <origin rpy="0 0 -3.0073" xyz="0.14 0 -0.0537"/>
    <parent link="right_leg2"/>
    <child link="right_wheel"/>
  </joint>
  <joint name="right_j5" type="fixed">
    <origin rpy="0 0 -2.8729" xyz="0.09 0 0"/>
    <parent link="right_motor"/>
    <child link="right_leg3"/>
  </joint>
  <!--TODO： Add close-chian -->
  <gazebo>
    <joint name="left_close_chain" type="fixed">
      <origin rpy="0 0 0" xyz="0.1 0 0"/>
      <parent link="left_leg3"/>
      <child link="left_leg2"/>
    </joint>
    <joint name="right_close_chain" type="fixed">
      <origin rpy="0 0 0" xyz="0.1 0 0"/>
      <parent link="right_leg3"/>
      <child link="right_leg2"/>
    </joint>
  </gazebo>
  <!-- Finish defining the robot's structure with all links and joints accurately reflecting the URDF structure -->
  <!--    <xacro:include filename="$(find upright_asset)/description/urdf/common/materials.xacro"/>-->
  <link name="arm_base_link">
    <inertial>
      <origin rpy="0 0 0" xyz="0.00006 -0.000046 0.0129"/>
      <mass value="6.722526"/>
      <inertia ixx="0.049640000000000004" ixy="-6.571312e-06" ixz="-9.063940000000001e-07" iyy="0.03882" iyz="2.1181100000000002e-07" izz="0.08303"/>
    </inertial>
    <visual>
      <origin rpy="0 0 0" xyz="0 0 0"/>
      <geometry>
        <mesh filename="package://upright_asset/description/meshes/manipulator/base_link.stl"/>
      </geometry>
      <material name="silver"/>
    </visual>
    <collision>
      <origin rpy="0 0 0" xyz="0 0 0"/>
      <geometry>
        <mesh filename="package://upright_asset/description/meshes/manipulator/base_link.stl"/>
      </geometry>
    </collision>
  </link>
  <link name="link1">
    <inertial>
      <origin rpy="0 0 0" xyz="0.000002 -0.00531 0.034685"/>
      <mass value="1.103721"/>
      <inertia ixx="0.0005726" ixy="-5.4105e-08" ixz="-3.821000000000001e-09" iyy="0.0004953000000000001" iyz="1.2915759e-05" izz="0.0005383"/>
    </inertial>
    <visual>
      <origin rpy="0 0 0" xyz="0 0 0"/>
      <geometry>
        <mesh filename="package://upright_asset/description/meshes/manipulator/link1.stl"/>
      </geometry>
      <material name="silver"/>
    </visual>
    <collision>
      <origin rpy="0 0 0" xyz="0 0 0"/>
      <geometry>
        <mesh filename="package://upright_asset/description/meshes/manipulator/link1.stl"/>
      </geometry>
    </collision>
  </link>
  <link name="link2">
    <inertial>
      <origin rpy="0 0 0" xyz="-0.197351 -0.002165 0.000057"/>
      <mass value="0.534276"/>
      <inertia ixx="0.0003837" ixy="-2.6179433000000002e-05" ixz="6.93218e-07" iyy="0.0018880000000000001" iyz="-5.850180000000001e-07" izz="0.00205"/>
    </inertial>
    <visual>
      <origin rpy="0 0 0" xyz="0 0 0"/>
      <geometry>
        <mesh filename="package://upright_asset/description/meshes/manipulator/link2.stl"/>
      </geometry>
      <material name="silver"/>
    </visual>
    <collision>
      <origin rpy="0 0 0" xyz="0 0 0"/>
      <geometry>
        <mesh filename="package://upright_asset/description/meshes/manipulator/link2.stl"/>
      </geometry>
    </collision>
  </link>
  <link name="link3">
    <inertial>
      <origin rpy="0 0 0" xyz="0.191296 -0.001405 0.053882"/>
      <mass value="0.474451"/>
      <inertia ixx="0.00032290000000000004" ixy="8.650968000000002e-06" ixz="-0.00023170000000000002" iyy="0.002226" iyz="1.036356e-06" izz="0.002291"/>
    </inertial>
    <visual>
      <origin rpy="0 0 0" xyz="0 0 0"/>
      <geometry>
        <mesh filename="package://upright_asset/description/meshes/manipulator/link3.stl"/>
      </geometry>
      <material name="silver"/>
    </visual>
    <collision>
      <origin rpy="0 0 0" xyz="0 0 0"/>
      <geometry>
        <mesh filename="package://upright_asset/description/meshes/manipulator/link3.stl"/>
      </geometry>
    </collision>
  </link>
  <link name="link4">
    <inertial>
      <origin rpy="0 0 0" xyz="0.02969 0.00192 0.03765"/>
      <mass value="0.056678"/>
      <inertia ixx="1.2622460000000002e-06" ixy="3.261e-08" ixz="-5.533339999999999e-07" iyy="1.3468290000000001e-06" iyz="4.118e-08" izz="9.75984e-07"/>
    </inertial>
    <visual>
      <origin rpy="0 0 0" xyz="0 0 0"/>
      <geometry>
        <mesh filename="package://upright_asset/description/meshes/manipulator/link4.stl"/>
      </geometry>
      <material name="silver"/>
    </visual>
    <collision>
      <origin rpy="0 0 0" xyz="0 0 0"/>
      <geometry>
        <mesh filename="package://upright_asset/description/meshes/manipulator/link4.stl"/>
      </geometry>
    </collision>
  </link>
  <link name="link5">
    <inertial>
      <origin rpy="0 0 0" xyz="0.001992 -0.000088 -0.053421"/>
      <mass value="0.598593"/>
      <inertia ixx="0.0007354000000000001" ixy="-4.49048e-07" ixz="3.7386443e-05" iyy="0.0007328" iyz="-2.1004300000000002e-07" izz="0.00023860000000000003"/>
    </inertial>
    <visual>
      <origin rpy="0 0 0" xyz="0 0 0"/>
      <geometry>
        <mesh filename="package://upright_asset/description/meshes/manipulator/link5.stl"/>
      </geometry>
      <material name="silver"/>
    </visual>
    <collision>
      <origin rpy="0 0 0" xyz="0 0 0"/>
      <geometry>
        <mesh filename="package://upright_asset/description/meshes/manipulator/link5.stl"/>
      </geometry>
    </collision>
  </link>
  <link name="link6">
    <inertial>
      <origin rpy="0 0 0" xyz="0 0 0"/>
      <mass value="0.001"/>
      <inertia ixx="1.0630412e-08" ixy="-1.0680000000000001e-19" ixz="8.357e-08" iyy="8.414108000000002e-06" iyz="0.0" izz="6.931832000000001e-06"/>
    </inertial>
    <visual>
      <origin rpy="0 0 0" xyz="0 0 0"/>
      <geometry>
        <mesh filename="package://upright_asset/description/meshes/manipulator/link6.stl"/>
      </geometry>
      <material name="silver"/>
    </visual>
    <collision>
      <origin rpy="0 0 0" xyz="0 0 0"/>
      <geometry>
        <mesh filename="package://upright_asset/description/meshes/manipulator/link6.stl"/>
      </geometry>
    </collision>
  </link>
  <joint name="joint1" type="revolute">
    <origin rpy="0 0 0" xyz="0 0 0.07925"/>
    <parent link="arm_base_link"/>
    <child link="link1"/>
    <axis xyz="0 0 1"/>
    <limit effort="150" lower="-1.57" upper="1.57" velocity="1.5"/>
  </joint>
  <joint name="joint2" type="revolute">
    <origin rpy="0 0 0" xyz="0 0 0.0365"/>
    <parent link="link1"/>
    <child link="link2"/>
    <axis xyz="0 1 0"/>
    <limit effort="150" lower="0" upper="1.57" velocity="1.5"/>
  </joint>
  <joint name="joint3" type="revolute">
    <origin rpy="0 0 0" xyz="-0.220 0 0"/>
    <parent link="link2"/>
    <child link="link3"/>
    <axis xyz="0 1 0"/>
    <limit effort="150" lower="-1.57" upper="0" velocity="1.5"/>
  </joint>
  <joint name="joint4" type="revolute">
    <origin rpy="0 0 0" xyz="0.220 0 0.057"/>
    <parent link="link3"/>
    <child link="link4"/>
    <axis xyz="0 1 0"/>
    <limit effort="150" lower="-1.5" upper="0.5" velocity="1.5"/>
  </joint>
  <joint name="joint5" type="revolute">
    <origin rpy="0 0 0" xyz="0.0615 0 0.0825"/>
    <parent link="link4"/>
    <child link="link5"/>
    <axis xyz="0 0 1"/>
    <limit effort="150" lower="-0.785" upper="0.785" velocity="1.5"/>
  </joint>
  <joint name="joint6" type="revolute">
    <origin rpy="0 0 0" xyz="0.0285 0 -0.0825"/>
    <parent link="link5"/>
    <child link="link6"/>
    <axis xyz="1 0 0"/>
    <limit effort="150" lower="-1.57" upper="1.57" velocity="1.5"/>
  </joint>
  <transmission name="joint1_tran">
    <type>transmission_interface/SimpleTransmission</type>
    <joint name="joint1">
      <hardwareInterface>hardware_interface/EffortJointInterface</hardwareInterface>
    </joint>
    <actuator name="joint1_motor">
      <hardwareInterface>hardware_interface/EffortJointInterface</hardwareInterface>
      <mechanicalReduction>1</mechanicalReduction>
    </actuator>
  </transmission>
  <transmission name="joint2_tran">
    <type>transmission_interface/SimpleTransmission</type>
    <joint name="joint2">
      <hardwareInterface>hardware_interface/EffortJointInterface</hardwareInterface>
    </joint>
    <actuator name="joint2_motor">
      <hardwareInterface>hardware_interface/EffortJointInterface</hardwareInterface>
      <mechanicalReduction>-1</mechanicalReduction>
    </actuator>
  </transmission>
  <transmission name="joint3_tran">
    <type>transmission_interface/SimpleTransmission</type>
    <joint name="joint3">
      <hardwareInterface>hardware_interface/EffortJointInterface</hardwareInterface>
    </joint>
    <actuator name="joint3_motor">
      <hardwareInterface>hardware_interface/EffortJointInterface</hardwareInterface>
      <mechanicalReduction>1</mechanicalReduction>
    </actuator>
  </transmission>
  <transmission name="joint4_tran">
    <type>transmission_interface/SimpleTransmission</type>
    <joint name="joint4">
      <hardwareInterface>hardware_interface/EffortJointInterface</hardwareInterface>
    </joint>
    <actuator name="joint4_motor">
      <hardwareInterface>hardware_interface/EffortJointInterface</hardwareInterface>
      <mechanicalReduction>-1</mechanicalReduction>
    </actuator>
  </transmission>
  <transmission name="joint5_tran">
    <type>transmission_interface/SimpleTransmission</type>
    <joint name="joint5">
      <hardwareInterface>hardware_interface/EffortJointInterface</hardwareInterface>
    </joint>
    <actuator name="joint5_motor">
      <hardwareInterface>hardware_interface/EffortJointInterface</hardwareInterface>
      <mechanicalReduction>-1</mechanicalReduction>
    </actuator>
  </transmission>
  <transmission name="joint6_tran">
    <type>transmission_interface/SimpleTransmission</type>
    <joint name="joint6">
      <hardwareInterface>hardware_interface/EffortJointInterface</hardwareInterface>
    </joint>
    <actuator name="joint6_motor">
      <hardwareInterface>hardware_interface/EffortJointInterface</hardwareInterface>
      <mechanicalReduction>1</mechanicalReduction>
    </actuator>
  </transmission>
  <gazebo>
    <plugin filename="libgazebo_ros_p3d.so" name="p3d_base_controller">
      <alwaysOn>true</alwaysOn>
      <updateRate>1000.0</updateRate>
      <bodyName>arm_base_link</bodyName>
      <topicName>ground_truth/state</topicName>
      <gaussianNoise>0</gaussianNoise>
      <frameName>world</frameName>
      <xyzOffsets>0 0 0</xyzOffsets>
      <rpyOffsets>0 0 0</rpyOffsets>
    </plugin>
  </gazebo>
  <joint name="manipulator_joint" type="fixed">
    <parent link="diablo_base_link"/>
    <child link="arm_base_link"/>
    <origin rpy="0.0 0.0 0.0" xyz="0.0 0.0 0.1"/>
  </joint>
  <gazebo>
    <plugin filename="libgazebo_ros_p3d.so" name="p3d_base_controller">
      <alwaysOn>true</alwaysOn>
      <updateRate>1000.0</updateRate>
      <bodyName>diablo_base_link</bodyName>
      <topicName>ground_truth/state</topicName>
      <gaussianNoise>0</gaussianNoise>
      <frameName>world</frameName>
      <xyzOffsets>0 0 0</xyzOffsets>
      <rpyOffsets>0 0 0</rpyOffsets>
    </plugin>
  </gazebo>
</robot>

