<?xml version="1.0" ?>
<!-- =================================================================================== -->
<!-- |    This document was autogenerated by xacro from robot.xacro                    | -->
<!-- |    EDITING THIS FILE BY HAND IS NOT RECOMMENDED                                 | -->
<!-- =================================================================================== -->
<robot name="diablo_manipulator">
  <material name="black">
    <color rgba="0.0 0.0 0.0 1.0"/>
  </material>
  <material name="blue">
    <color rgba="0.0 0.0 0.8 1.0"/>
  </material>
  <material name="green">
    <color rgba="0.0 0.8 0.0 1.0"/>
  </material>
  <material name="grey">
    <color rgba="0.2 0.2 0.2 1.0"/>
  </material>
  <material name="silver">
    <color rgba="0.9137254901960784 0.9137254901960784 0.8470588235294118 1.0"/>
  </material>
  <material name="orange">
    <color rgba="1.0 0.4235294117647059 0.0392156862745098 1.0"/>
  </material>
  <material name="brown">
    <color rgba="0.8705882352941177 0.8117647058823529 0.7647058823529411 1.0"/>
  </material>
  <material name="red">
    <color rgba="0.8 0.0 0.0 1.0"/>
  </material>
  <material name="white">
    <color rgba="1.0 1.0 1.0 1.0"/>
  </material>
  <link name="diablo_base_link">
    <inertial>
      <origin rpy="0 0 0" xyz="0 0 0"/>
      <mass value="11.639"/>
      <inertia ixx="0.071628" ixy="-5.9879e-09" ixz="-0.00097471" iyy="0.16274" iyz="-1.6369e-08" izz="0.14673"/>
    </inertial>
    <visual>
      <origin rpy="0 0 0" xyz="0 0 0"/>
      <geometry>
        <mesh filename="package://upright_asset/description/meshes/diablo/base_link.STL"/>
      </geometry>
      <material name="grey"/>
    </visual>
    <collision>
      <origin rpy="0 0 0" xyz="0 0 0"/>
      <geometry>
        <mesh filename="package://upright_asset/description/meshes/diablo/base_link.STL"/>
      </geometry>
    </collision>
  </link>
  <link name="left_motor">
    <inertial>
      <origin rpy="0 0 0" xyz="0 0 0"/>
      <mass value="1.3837"/>
      <inertia ixx="0.003352" ixy="2.7785e-09" ixz="-6.5913e-05" iyy="0.0034908" iyz="4.5045e-10" izz="0.0034856"/>
    </inertial>
    <visual>
      <origin rpy="0 0 0" xyz="0 0 0"/>
      <geometry>
        <mesh filename="package://upright_asset/description/meshes/diablo/left_motor.STL"/>
      </geometry>
      <material name="silver"/>
    </visual>
    <collision>
      <origin rpy="0 0 0" xyz="0 0 0"/>
      <geometry>
        <mesh filename="package://upright_asset/description/meshes/diablo/left_motor.STL"/>
      </geometry>
    </collision>
  </link>
  <link name="left_leg1">
    <inertial>
      <origin rpy="0 0 0" xyz="0 0 0"/>
      <mass value="0.10382"/>
      <inertia ixx="3.6972e-05" ixy="2.4106e-05" ixz="4.3699e-10" iyy="0.00029278" iyz="-4.1243e-11" izz="0.00032532"/>
    </inertial>
    <visual>
      <origin rpy="0 0 0" xyz="0 0 0"/>
      <geometry>
        <mesh filename="package://upright_asset/description/meshes/diablo/left_leg1.STL"/>
      </geometry>
      <material name="silver"/>
    </visual>
    <collision>
      <origin rpy="0 0 0" xyz="0 0 0"/>
      <geometry>
        <mesh filename="package://upright_asset/description/meshes/diablo/left_leg1.STL"/>
      </geometry>
    </collision>
  </link>
  <link name="left_leg2">
    <inertial>
      <origin rpy="0 0 0" xyz="0 0 0"/>
      <mass value="0.18218"/>
      <inertia ixx="4.1372e-05" ixy="5.1445e-09" ixz="-7.3659e-06" iyy="0.00048219" iyz="2.5521e-11" izz="0.00050441"/>
    </inertial>
    <visual>
      <origin rpy="0 0 0" xyz="0 0 0"/>
      <geometry>
        <mesh filename="package://upright_asset/description/meshes/diablo/left_leg2.STL"/>
      </geometry>
      <material name="silver"/>
    </visual>
    <collision>
      <origin rpy="0 0 0" xyz="0 0 0"/>
      <geometry>
        <mesh filename="package://upright_asset/description/meshes/diablo/left_leg2.STL"/>
      </geometry>
    </collision>
  </link>
  <link name="left_wheel">
    <inertial>
      <origin rpy="0 0 0" xyz="0 0 0"/>
      <mass value="2.9494"/>
      <inertia ixx="0.0069338" ixy="2.8693e-09" ixz="4.6779e-09" iyy="0.006934" iyz="-5.0441e-11" izz="0.012567"/>
    </inertial>
    <visual>
      <origin rpy="0 0 0" xyz="0 0 0"/>
      <geometry>
        <mesh filename="package://upright_asset/description/meshes/diablo/left_wheel.STL"/>
      </geometry>
      <material name="black"/>
    </visual>
    <collision>
      <origin rpy="0 0 0" xyz="0 0 0"/>
      <geometry>
        <mesh filename="package://upright_asset/description/meshes/diablo/left_wheel.STL"/>
      </geometry>
    </collision>
  </link>
  <link name="left_leg3">
    <inertial>
      <origin rpy="0 0 0" xyz="0 0 0"/>
      <mass value="0.071103"/>
      <inertia ixx="1.6657e-05" ixy="-5.5246e-06" ixz="3.9598e-14" iyy="0.00017966" iyz="-6.5493e-15" izz="0.00019328"/>
    </inertial>
    <visual>
      <origin rpy="0 0 0" xyz="0 0 0"/>
      <geometry>
        <mesh filename="package://upright_asset/description/meshes/diablo/left_leg3.STL"/>
      </geometry>
      <material name="brown"/>
    </visual>
    <collision>
      <origin rpy="0 0 0" xyz="0 0 0"/>
      <geometry>
        <mesh filename="package://upright_asset/description/meshes/diablo/left_leg3.STL"/>
      </geometry>
    </collision>
  </link>
  <link name="right_motor">
    <inertial>
      <origin rpy="0 0 0" xyz="0 0 0"/>
      <mass value="1.3838"/>
      <inertia ixx="0.003352" ixy="-2.6527e-09" ixz="6.5914e-05" iyy="0.0034908" iyz="-7.2968e-10" izz="0.0034856"/>
    </inertial>
    <visual>
      <origin rpy="0 0 0" xyz="0 0 0"/>
      <geometry>
        <mesh filename="package://upright_asset/description/meshes/diablo/right_motor.STL"/>
      </geometry>
      <material name="silver"/>
    </visual>
    <collision>
      <origin rpy="0 0 0" xyz="0 0 0"/>
      <geometry>
        <mesh filename="package://upright_asset/description/meshes/diablo/right_motor.STL"/>
      </geometry>
    </collision>
  </link>
  <link name="right_leg1">
    <inertial>
      <origin rpy="0 0 0" xyz="0 0 0"/>
      <mass value="0.10382"/>
      <inertia ixx="3.6972e-05" ixy="2.4106e-05" ixz="-4.3686e-10" iyy="0.00029278" iyz="4.1459e-11" izz="0.00032532"/>
    </inertial>
    <visual>
      <origin rpy="0 0 0" xyz="0 0 0"/>
      <geometry>
        <mesh filename="package://upright_asset/description/meshes/diablo/right_leg1.STL"/>
      </geometry>
      <material name="silver"/>
    </visual>
    <collision>
      <origin rpy="0 0 0" xyz="0 0 0"/>
      <geometry>
        <mesh filename="package://upright_asset/description/meshes/diablo/right_leg1.STL"/>
      </geometry>
    </collision>
  </link>
  <link name="right_leg2">
    <inertial>
      <origin rpy="0 0 0" xyz="0 0 0"/>
      <mass value="0.18218"/>
      <inertia ixx="4.1372e-05" ixy="5.1777e-09" ixz="7.3659e-06" iyy="0.00048219" iyz="4.5225e-11" izz="0.00050441"/>
    </inertial>
    <visual>
      <origin rpy="0 0 0" xyz="0 0 0"/>
      <geometry>
        <mesh filename="package://upright_asset/description/meshes/diablo/right_leg2.STL"/>
      </geometry>
      <material name="silver"/>
    </visual>
    <collision>
      <origin rpy="0 0 0" xyz="0 0 0"/>
      <geometry>
        <mesh filename="package://upright_asset/description/meshes/diablo/right_leg2.STL"/>
      </geometry>
    </collision>
  </link>
  <link name="right_wheel">
    <inertial>
      <origin rpy="0 0 0" xyz="0 0 0"/>
      <mass value="2.9494"/>
      <inertia ixx="0.0069339" ixy="-1.3146e-07" ixz="-3.0392e-09" iyy="0.0069339" iyz="-3.5756e-09" izz="0.012567"/>
    </inertial>
    <visual>
      <origin rpy="0 0 0" xyz="0 0 0"/>
      <geometry>
        <mesh filename="package://upright_asset/description/meshes/diablo/right_wheel.STL"/>
      </geometry>
      <material name="black"/>
    </visual>
    <collision>
      <origin rpy="0 0 0" xyz="0 0 0"/>
      <geometry>
        <mesh filename="package://upright_asset/description/meshes/diablo/right_wheel.STL"/>
      </geometry>
    </collision>
  </link>
  <link name="right_leg3">
    <inertial>
      <origin rpy="0 0 0" xyz="0 0 0"/>
      <mass value="0.071103"/>
      <inertia ixx="1.6657e-05" ixy="-5.5246e-06" ixz="1.4852e-14" iyy="0.00017966" iyz="-6.5194e-14" izz="0.00019328"/>
    </inertial>
    <visual>
      <origin rpy="0 0 0" xyz="0 0 0"/>
      <geometry>
        <mesh filename="package://upright_asset/description/meshes/diablo/right_leg3.STL"/>
      </geometry>
      <material name="brown"/>
    </visual>
    <collision>
      <origin rpy="0 0 0" xyz="0 0 0"/>
      <geometry>
        <mesh filename="package://upright_asset/description/meshes/diablo/right_leg3.STL"/>
      </geometry>
    </collision>
  </link>
  <joint name="left_j4" type="fixed">
    <origin rpy="1.5708 0.13433 -3.1416" xyz="0 0.18755 0"/>
    <parent link="diablo_base_link"/>
    <child link="left_motor"/>
  </joint>
  <joint name="left_j1" type="fixed">
    <origin rpy="0 0 -2.8729" xyz="0 0 0"/>
    <parent link="left_motor"/>
    <child link="left_leg1"/>
  </joint>
  <joint name="left_j2" type="fixed">
    <origin rpy="0 0 2.8729" xyz="0.14 0 0"/>
    <parent link="left_leg1"/>
    <child link="left_leg2"/>
  </joint>
  <joint name="left_j3" type="continuous">
    <origin rpy="0 0 0.13433" xyz="0.14 0 0.0537"/>
    <parent link="left_leg2"/>
    <child link="left_wheel"/>
    <axis xyz="0 0 -1"/>
  </joint>
  <joint name="left_j5" type="fixed">
    <origin rpy="0 0 -2.8729" xyz="0.09 0 0"/>
    <parent link="left_motor"/>
    <child link="left_leg3"/>
  </joint>
  <joint name="right_j4" type="fixed">
    <origin rpy="1.5708 0.13433 3.1416" xyz="0 -0.18755 0"/>
    <parent link="diablo_base_link"/>
    <child link="right_motor"/>
  </joint>
  <joint name="right_j1" type="fixed">
    <origin rpy="0 0 -2.8729" xyz="0 0 0"/>
    <parent link="right_motor"/>
    <child link="right_leg1"/>
  </joint>
  <joint name="right_j2" type="fixed">
    <origin rpy="0 0 2.8729" xyz="0.14 0 0"/>
    <parent link="right_leg1"/>
    <child link="right_leg2"/>
    <axis xyz="0 0 1"/>
  </joint>
  <joint name="right_j3" type="continuous">
    <origin rpy="0 0 -3.0073" xyz="0.14 0 -0.0537"/>
    <parent link="right_leg2"/>
    <child link="right_wheel"/>
    <axis xyz="0 0 -1"/>
  </joint>
  <joint name="right_j5" type="fixed">
    <origin rpy="0 0 -2.8729" xyz="0.09 0 0"/>
    <parent link="right_motor"/>
    <child link="right_leg3"/>
  </joint>
  <gazebo>
    <plugin filename="libgazebo_ros_p3d.so" name="p3d_base_controller">
      <alwaysOn>true</alwaysOn>
      <updateRate>1000.0</updateRate>
      <bodyName>diablo_base_link</bodyName>
      <topicName>ground_truth/state</topicName>
      <gaussianNoise>0</gaussianNoise>
      <frameName>world</frameName>
      <xyzOffsets>0 0 0</xyzOffsets>
      <rpyOffsets>0 0 0</rpyOffsets>
    </plugin>
  </gazebo>
  <!--    <xacro:include filename="$(find upright_asset)/description/urdf/diablo/imu.xacro"/>-->
  <link name="arm_base_link">
    <inertial>
      <origin rpy="0 0 0" xyz="0 0 0"/>
      <mass value="0.775915"/>
      <inertia ixx="0.000699851" ixy="5.34515e-06" ixz="1.76381e-06" iyy="0.000855522" iyz="3.90737e-06" izz="0.00105822"/>
    </inertial>
    <visual>
      <origin rpy="0 0 0" xyz="0 0 0"/>
      <geometry>
        <mesh filename="package://upright_asset/description/meshes/manipulator/base_link.STL"/>
      </geometry>
      <material name="grey"/>
    </visual>
    <collision>
      <origin rpy="0 0 0" xyz="0 0 0"/>
      <geometry>
        <mesh filename="package://upright_asset/description/meshes/manipulator/base_link.STL"/>
      </geometry>
    </collision>
  </link>
  <link name="link1">
    <inertial>
      <origin rpy="0 0 0" xyz="0 0 0"/>
      <mass value="0.557107"/>
      <inertia ixx="0.000301325" ixy="-2.99504e-07" ixz="4.81746e-07" iyy="0.000250218" iyz="1.49548e-05" izz="0.000325679"/>
    </inertial>
    <visual>
      <origin rpy="0 0 0" xyz="0 0 0"/>
      <geometry>
        <mesh filename="package://upright_asset/description/meshes/manipulator/link1.STL"/>
      </geometry>
      <material name="grey"/>
    </visual>
    <collision>
      <origin rpy="0 0 0" xyz="0 0 0"/>
      <geometry>
        <mesh filename="package://upright_asset/description/meshes/manipulator/link1.STL"/>
      </geometry>
    </collision>
  </link>
  <link name="link2">
    <inertial>
      <origin rpy="0 0 0" xyz="0 0 0"/>
      <mass value="0.646249"/>
      <inertia ixx="0.000351883" ixy="-7.83179e-05" ixz="8.22451e-05" iyy="0.0019526" iyz="1.74745e-05" izz="0.00195686"/>
    </inertial>
    <visual>
      <origin rpy="0 0 0" xyz="0 0 0"/>
      <geometry>
        <mesh filename="package://upright_asset/description/meshes/manipulator/link2.STL"/>
      </geometry>
      <material name="grey"/>
    </visual>
    <collision>
      <origin rpy="0 0 0" xyz="0 0 0"/>
      <geometry>
        <mesh filename="package://upright_asset/description/meshes/manipulator/link2.STL"/>
      </geometry>
    </collision>
  </link>
  <link name="link3">
    <inertial>
      <origin rpy="0 0 0" xyz="0 0 0"/>
      <mass value="0.445563"/>
      <inertia ixx="0.00016737" ixy="-4.81066e-07" ixz="1.7795e-06" iyy="0.000672323" iyz="-9.83781e-08" izz="0.000686599"/>
    </inertial>
    <visual>
      <origin rpy="0 0 0" xyz="0 0 0"/>
      <geometry>
        <mesh filename="package://upright_asset/description/meshes/manipulator/link3.STL"/>
      </geometry>
      <material name="grey"/>
    </visual>
    <collision>
      <origin rpy="0 0 0" xyz="0 0 0"/>
      <geometry>
        <mesh filename="package://upright_asset/description/meshes/manipulator/link3.STL"/>
      </geometry>
    </collision>
  </link>
  <link name="link4">
    <inertial>
      <origin rpy="0 0 0" xyz="0 0 0"/>
      <mass value="0.345885"/>
      <inertia ixx="0.000133803" ixy="-7.29532e-09" ixz="-2.46488e-07" iyy="0.000121205" iyz="9.89248e-10" izz="0.00012501"/>
    </inertial>
    <visual>
      <origin rpy="0 0 0" xyz="0 0 0"/>
      <geometry>
        <mesh filename="package://upright_asset/description/meshes/manipulator/link4.STL"/>
      </geometry>
      <material name="grey"/>
    </visual>
    <collision>
      <origin rpy="0 0 0" xyz="0 0 0"/>
      <geometry>
        <mesh filename="package://upright_asset/description/meshes/manipulator/link4.STL"/>
      </geometry>
    </collision>
  </link>
  <link name="link5">
    <inertial>
      <origin rpy="0 0 0" xyz="0 0 0"/>
      <mass value="0.186636"/>
      <inertia ixx="0.000101781" ixy="-1.53593e-08" ixz="5.24141e-08" iyy="8.27871e-05" iyz="-1.71996e-08" izz="8.59348e-05"/>
    </inertial>
    <visual>
      <origin rpy="0 0 0" xyz="0 0 0"/>
      <geometry>
        <mesh filename="package://upright_asset/description/meshes/manipulator/link5.STL"/>
      </geometry>
      <material name="grey"/>
    </visual>
    <collision>
      <origin rpy="0 0 0" xyz="0 0 0"/>
      <geometry>
        <mesh filename="package://upright_asset/description/meshes/manipulator/link5.STL"/>
      </geometry>
    </collision>
  </link>
  <link name="link6">
    <inertial>
      <origin rpy="0 0 0" xyz="0 0 0"/>
      <mass value="0.174621"/>
      <inertia ixx="5.00435e-05" ixy="0" ixz="0" iyy="5.00435e-05" iyz="0" izz="3.8504e-05"/>
    </inertial>
    <visual>
      <origin rpy="0 0 0" xyz="0 0 0"/>
      <geometry>
        <mesh filename="package://upright_asset/description/meshes/manipulator/link6.STL"/>
      </geometry>
      <material name="grey"/>
    </visual>
    <collision>
      <origin rpy="0 0 0" xyz="0 0 0"/>
      <geometry>
        <mesh filename="package://upright_asset/description/meshes/manipulator/link6.STL"/>
      </geometry>
    </collision>
  </link>
  <joint name="joint1" type="continuous">
    <origin rpy="0 0 0" xyz="0 0 0.1127"/>
    <parent link="arm_base_link"/>
    <child link="link1"/>
    <axis xyz="0 0 1"/>
  </joint>
  <joint name="joint2" type="continuous">
    <origin rpy="-1.5708 -0.38678 3.1416" xyz="0 0 0"/>
    <parent link="link1"/>
    <child link="link2"/>
    <axis xyz="0 0 1"/>
  </joint>
  <joint name="joint3" type="continuous">
    <origin rpy="0 0 -2.7548" xyz="0.27009 1.3718E-05 0"/>
    <parent link="link2"/>
    <child link="link3"/>
    <axis xyz="0 0 1"/>
  </joint>
  <joint name="joint4" type="continuous">
    <origin rpy="-1.5708 0 -1.5708" xyz="0.30854 0.0027492 0.00019049"/>
    <parent link="link3"/>
    <child link="link4"/>
    <axis xyz="0 0 1"/>
  </joint>
  <joint name="joint5" type="continuous">
    <origin rpy="0 -1.5708 0" xyz="0 0 0"/>
    <parent link="link4"/>
    <child link="link5"/>
    <axis xyz="0 0 1"/>
  </joint>
  <joint name="joint6" type="continuous">
    <origin rpy="0 1.5708 0" xyz="0.0865 0 -0.0027486"/>
    <parent link="link5"/>
    <child link="link6"/>
    <axis xyz="0 0 1"/>
  </joint>
  <joint name="manipulator_joint" type="fixed">
    <parent link="diablo_base_link"/>
    <child link="arm_base_link"/>
    <origin rpy="0.0 0.0 0.0" xyz="0.0 0.0 0.1"/>
  </joint>
</robot>

